Workbook

Sheet Compound Classes
A1: From Sephton, M. A. Organic compounds in carbonaceous meteorites. Nat. Prod. Rep. 19, 292–311 (2002).
A2: * reported as a range, value is represents the median
A3: ‡ reported as a minimum value
A5: compound class | B5: ug/g | C5: percent of total organic matter
A6: Aliphatic and aromatic hydrocarbons | C6: =SUM(C7:C8) -> 6.1201591
A7: Aliphatic hydrocarbons* | B7: 23.5 | C7: 3.1960831
A8: Aromatic hydrocarbons* | B8: 21.5 | C8: 2.924076
A9: Polar Hydrocarbons | B9: 38 | C9: 5.1681344
A10: monocarboxylic acids | B10: 332 | C10: 45.153174
A11: dicarboxylic acids | B11: 25.7 | C11: 3.4952909
A12: amino acids | B12: 60 | C12: 8.1602122
A13: hydroxy acids | B13: 14.6 | C13: 1.9856516
A14: dicarboximides‡ | B14: 50 | C14: 6.8001768
A15: pyridine carboxylic acids‡ | B15: 7 | C15: 0.95202475
A16: sulfonic acids | B16: 67 | C16: 9.1122369
A17: phosphonic acids | B17: 1.5 | C17: 0.2040053
A18: n-heterocycles* | B18: 0.275 | C18: 0.037400972
A19: amines | B19: 8 | C19: 1.0880283
A20: amides | B20: trace
A21: polyols | B21: 60 | C21: 8.1602122
A22: purines | B22: 1.2 | C22: 0.16320424
A23: urea | B23: 25 | C23: 3.4000884
B24: 735.275 | C24: 100

Sheet All compounds
A1: compound class | B1: Column1 | C1: percent by weight of each compound class | D1: Include in soup? | E1: include numerical | F1: compound | G1: citation | H1: nmol/g of meteorite | I1: mw | J1: ng compound/g meteorite | K1: ng each compound class | L1: grams for 100 g of soup | M1: comments | N1: Density | O1: measured | P1: Column2
A2: Aliphatic and aromatic hydrocarbons | B2: =VLOOKUP(A2, 'Compound Classes'!$A$6:$C$23, 3, FALSE) -> 6.1201591 | C2: 6.12 | D2: yes | E2: =IF(D2="yes",1,0) -> 1 | F2: mineral oil | G2: Kissin, Y. V. Hydrocarbon components in carbonaceous meteorites. Geochim. Cosmochim. Acta 67, 1723–1735 (2003). | H2: not given | I2: none | L2: 6.12 | M2: mineral oil hydrocarbons are a bit larger than the hydrocarbons in Murchison, but does an approximate job at generating an oil phase
A3: Amines | B3: =VLOOKUP(A3, 'Compound Classes'!$A$6:$C$23, 3, FALSE) -> 1.0880283 | C3: 1.05 | D3: yes | E3: =IF(D3="yes",1,0) -> 1 | F3: Methylamine | G3: Pizzarello, S., Feng, X., Epstein, S., & Cronin, J. R. (1994). Isotopic analyses of nitrogenous compounds from the Murchison meteorite: ammonia, amines, amino acids, and polar hydrocarbons. Geochimica et Cosmochimica Acta, 58(24), 5579–5587. https://doi.org/10.1016/0016-7037(94)90251-9 | H3: 71 | I3: 31.06 | J3: =H3*I3 -> 2205.26 | K3: =SUMIF(D3:D4,"=yes",J3:J4) -> 3016.7 | L3: =J3*E3/K3*C3 -> 0.7675682 | N3: 0.897 | O3: 0.7623 | P3: STINKY
A4: Amines | B4: =VLOOKUP(A4, 'Compound Classes'!$A$6:$C$23, 3, FALSE) -> 1.0880283 | C4: 1.05 | D4: yes | E4: =IF(D4="yes",1,0) -> 1 | F4: Ethylamine | G4: Pizzarello, S., Feng, X., Epstein, S., & Cronin, J. R. (1994). Isotopic analyses of nitrogenous compounds from the Murchison meteorite: ammonia, amines, amino acids, and polar hydrocarbons. Geochimica et Cosmochimica Acta, 58(24), 5579–5587. https://doi.org/10.1016/0016-7037(94)90251-10 | H4: 18 | I4: 45.08 | J4: =H4*I4 -> 811.44 | K4: =SUMIFS(J$2:J$116,A$2:A$116,A4,D$2:D$116,"=yes") -> 3016.7 | L4: =J4*E4/K4*C4 -> 0.2824318 | O4: 0.28 | P4: Bubble In
A5: Amino acids | B5: =VLOOKUP(A5, 'Compound Classes'!$A$6:$C$23, 3, FALSE) -> 8.1602122 | C5: 7.89 | D5: yes | E5: =IF(D5="yes",1,0) -> 1 | F5: valine | G5: Cronin, J. R., & Pizzarello, S. (1983). Amino acids in meteorites. Advances in Space Research, 3(9), 5–18. https://doi.org/10.1016/0273-1177(83)90036-13 | H5: 10 | I5: 117.15 | J5: =H5*I5 -> 1171.5 | K5: =SUMIFS(J$2:J$116,A$2:A$116,A5,D$2:D$116,"=yes") -> 39554.99 | L5: =J5*E5/K5*C5 -> 0.2336781 | O5: 0.2324
A6: Amino acids | B6: =VLOOKUP(A6, 'Compound Classes'!$A$6:$C$23, 3, FALSE) -> 8.1602122 | C6: 7.89 | D6: yes | E6: =IF(D6="yes",1,0) -> 1 | F6: beta-alanine | G6: Cronin, J. R., & Pizzarello, S. (1983). Amino acids in meteorites. Advances in Space Research, 3(9), 5–18. https://doi.org/10.1016/0273-1177(83)90036-6 | H6: 14 | I6: 89.09 | J6: =H6*I6 -> 1247.26 | K6: =SUMIFS(J$2:J$116,A$2:A$116,A6,D$2:D$116,"=yes") -> 39554.99 | L6: =J6*E6/K6*C6 -> 0.24878988 | O6: 0.2496
A7: Amino acids | B7: =VLOOKUP(A7, 'Compound Classes'!$A$6:$C$23, 3, FALSE) -> 8.1602122 | C7: 7.89 | D7: yes | E7: =IF(D7="yes",1,0) -> 1 | F7: sarcosine | G7: Cronin, J. R., & Pizzarello, S. (1983). Amino acids in meteorites. Advances in Space Research, 3(9), 5–18. https://doi.org/10.1016/0273-1177(83)90036-7 | H7: 19 | I7: 89.09 | J7: =H7*I7 -> 1692.71 | K7: =SUMIFS(J$2:J$116,A$2:A$116,A7,D$2:D$116,"=yes") -> 39554.99 | L7: =J7*E7/K7*C7 -> 0.33764341 | P7: 444
A8: Amino acids | B8: =VLOOKUP(A8, 'Compound Classes'!$A$6:$C$23, 3, FALSE) -> 8.1602122 | C8: 7.89 | D8: yes | E8: =IF(D8="yes",1,0) -> 1 | F8: proline | G8: Cronin, J. R., & Pizzarello, S. (1983). Amino acids in meteorites. Advances in Space Research, 3(9), 5–18. https://doi.org/10.1016/0273-1177(83)90036-17 | H8: 16 | I8: 115.13 | J8: =H8*I8 -> 1842.08 | K8: =SUMIFS(J$2:J$116,A$2:A$116,A8,D$2:D$116,"=yes") -> 39554.99 | L8: =J8*E8/K8*C8 -> 0.36743812 | O8: 0.367
A9: Amino acids | B9: =VLOOKUP(A9, 'Compound Classes'!$A$6:$C$23, 3, FALSE) -> 8.1602122 | C9: 7.89 | D9: yes | E9: =IF(D9="yes",1,0) -> 1 | F9: alpha-aminobutyric acid | G9: Cronin, J. R., & Pizzarello, S. (1983). Amino acids in meteorites. Advances in Space Research, 3(9), 5–18. https://doi.org/10.1016/0273-1177(83)90036-8 | H9: 18 | I9: 103.12 | J9: =H9*I9 -> 1856.16 | K9: =SUMIFS(J$2:J$116,A$2:A$116,A9,D$2:D$116,"=yes") -> 39554.99 | L9: =J9*E9/K9*C9 -> 0.37024665 | O9: 0.3707
A10: Amino acids | B10: =VLOOKUP(A10, 'Compound Classes'!$A$6:$C$23, 3, FALSE) -> 8.1602122 | C10: 7.89 | D10: yes | E10: =IF(D10="yes",1,0) -> 1 | F10: gamma-aminobutyric acid | G10: Cronin, J. R., & Pizzarello, S. (1983). Amino acids in meteorites. Advances in Space Research, 3(9), 5–18. https://doi.org/10.1016/0273-1177(83)90036-12 | H10: 24 | I10: 103.12 | J10: =H10*I10 -> 2474.88 | K10: =SUMIFS(J$2:J$116,A$2:A$116,A10,D$2:D$116,"=yes") -> 39554.99 | L10: =J10*E10/K10*C10 -> 0.4936622 | O10: 0.495
A11: Amino acids | B11: =VLOOKUP(A11, 'Compound Classes'!$A$6:$C$23, 3, FALSE) -> 8.1602122 | C11: 7.89 | D11: yes | E11: =IF(D11="yes",1,0) -> 1 | F11: glutamic acid | G11: Cronin, J. R., & Pizzarello, S. (1983). Amino acids in meteorites. Advances in Space Research, 3(9), 5–18. https://doi.org/10.1016/0273-1177(83)90036-21 | H11: 18 | I11: 147.13 | J11: =H11*I11 -> 2648.34 | K11: =SUMIFS(J$2:J$116,A$2:A$116,A11,D$2:D$116,"=yes") -> 39554.99 | L11: =J11*E11/K11*C11 -> 0.52826211 | O11: 0.5272
A12: Amino acids | B12: =VLOOKUP(A12, 'Compound Classes'!$A$6:$C$23, 3, FALSE) -> 8.1602122 | C12: 7.89 | D12: yes | E12: =IF(D12="yes",1,0) -> 1 | F12: isovaline | G12: Cronin, J. R., & Pizzarello, S. (1983). Amino acids in meteorites. Advances in Space Research, 3(9), 5–18. https://doi.org/10.1016/0273-1177(83)90036-14 | H12: 28 | I12: 117.15 | J12: =H12*I12 -> 3280.2 | K12: =SUMIFS(J$2:J$116,A$2:A$116,A12,D$2:D$116,"=yes") -> 39554.99 | L12: =J12*E12/K12*C12 -> 0.65429869 | O12: 0.654
A13: Amino acids | B13: =VLOOKUP(A13, 'Compound Classes'!$A$6:$C$23, 3, FALSE) -> 8.1602122 | C13: 7.89 | D13: yes | E13: =IF(D13="yes",1,0) -> 1 | F13: alanine | G13: Cronin, J. R., & Pizzarello, S. (1983). Amino acids in meteorites. Advances in Space Research, 3(9), 5–18. https://doi.org/10.1016/0273-1177(83)90036-5 | H13: 44 | I13: 89.09 | J13: =H13*I13 -> 3919.96 | K13: =SUMIFS(J$2:J$116,A$2:A$116,A13,D$2:D$116,"=yes") -> 39554.99 | L13: =J13*E13/K13*C13 -> 0.78191107 | O13: 0.7821
A14: Amino acids | B14: =VLOOKUP(A14, 'Compound Classes'!$A$6:$C$23, 3, FALSE) -> 8.1602122 | C14: 7.89 | D14: yes | E14: =IF(D14="yes",1,0) -> 1 | F14: glycine | G14: Cronin, J. R., & Pizzarello, S. (1983). Amino acids in meteorites. Advances in Space Research, 3(9), 5–18. https://doi.org/10.1016/0273-1177(83)90036-4 | H14: 98 | I14: 75.07 | J14: =H14*I14 -> 7356.86 | K14: =SUMIFS(J$2:J$116,A$2:A$116,A14,D$2:D$116,"=yes") -> 39554.99 | L14: =J14*E14/K14*C14 -> 1.4674666 | O14: 1.469
A15: Amino acids | B15: =VLOOKUP(A15, 'Compound Classes'!$A$6:$C$23, 3, FALSE) -> 8.1602122 | C15: 7.89 | D15: yes | E15: =IF(D15="yes",1,0) -> 1 | F15: alpha-aminoisobutyric acid | G15: Cronin, J. R., & Pizzarello, S. (1983). Amino acids in meteorites. Advances in Space Research, 3(9), 5–18. https://doi.org/10.1016/0273-1177(83)90036-9 | H15: 117 | I15: 103.12 | J15: =H15*I15 -> 12065.04 | K15: =SUMIFS(J$2:J$116,A$2:A$116,A15,D$2:D$116,"=yes") -> 39554.99 | L15: =J15*E15/K15*C15 -> 2.4066032 | O15: 2.4054
A16: dicarboximides‡ | B16: =VLOOKUP(A16, 'Compound Classes'!$A$6:$C$23, 3, FALSE) -> 6.8001768 | C16: 6.58 | D16: yes | E16: =IF(D16="yes",1,0) -> 1 | F16: adipamic acid | G16: Cooper, G. W., & Cronin, J. R. (1995). Linear and cyclic aliphatic carboxamides of the Murchison meteorite: Hydrolyzable derivatives of amino acids and other carboxylic acids. Geochimica et Cosmochimica Acta, 59(5), 1003–1015. https://doi.org/https://doi.org/10.1016/0016-7037(95)00018-8 | H16: 50 | I16: 145.16 | J16: =H16*I16 -> 7258 | K16: =SUMIFS(J$2:J$116,A$2:A$116,A16,D$2:D$116,"=yes") -> 43791 | L16: =J16*E16/K16*C16 -> 1.0905812 | P16: No Stock
A17: dicarboximides‡ | B17: =VLOOKUP(A17, 'Compound Classes'!$A$6:$C$23, 3, FALSE) -> 6.8001768 | C17: 6.58 | D17: yes | E17: =IF(D17="yes",1,0) -> 1 | F17: glutaramic acid | G17: Cooper, G. W., & Cronin, J. R. (1995). Linear and cyclic aliphatic carboxamides of the Murchison meteorite: Hydrolyzable derivatives of amino acids and other carboxylic acids. Geochimica et Cosmochimica Acta, 59(5), 1003–1015. https://doi.org/https://doi.org/10.1016/0016-7037(95)00018-7 | H17: 100 | I17: 131.13 | J17: =H17*I17 -> 13113 | K17: =SUMIFS(J$2:J$116,A$2:A$116,A17,D$2:D$116,"=yes") -> 43791 | L17: =J17*E17/K17*C17 -> 1.9703487 | P17: No Stock
A18: dicarboximides‡ | B18: =VLOOKUP(A18, 'Compound Classes'!$A$6:$C$23, 3, FALSE) -> 6.8001768 | C18: 6.58 | D18: yes | E18: =IF(D18="yes",1,0) -> 1 | F18: succinamic acid | G18: Cooper, G. W., & Cronin, J. R. (1995). Linear and cyclic aliphatic carboxamides of the Murchison meteorite: Hydrolyzable derivatives of amino acids and other carboxylic acids. Geochimica et Cosmochimica Acta, 59(5), 1003–1015. https://doi.org/https://doi.org/10.1016/0016-7037(95)00018-6 | H18: 200 | I18: 117.1 | J18: =H18*I18 -> 23420 | K18: =SUMIFS(J$2:J$116,A$2:A$116,A18,D$2:D$116,"=yes") -> 43791 | L18: =J18*E18/K18*C18 -> 3.5190701 | O18: 3.5215
A19: Dicarboxylic acids | B19: =VLOOKUP(A19, 'Compound Classes'!$A$6:$C$23, 3, FALSE) -> 3.4952909 | C19: 3.38 | D19: yes | E19: =IF(D19="yes",1,0) -> 1 | F19: methyl succinic | G19: Pizzarello, S., & Huang, Y. (2002). Molecular and isotopic analyses of Tagish Lake alkyl dicarboxylic acids. Meteoritics and Planetary Science, 37(5), 687–696. https://doi.org/10.1111/j.1945-5100.2002.tb00848.x | H19: 16 | I19: 132.11 | J19: =H19*I19 -> 2113.76 | K19: =SUMIFS(J$2:J$116,A$2:A$116,A19,D$2:D$116,"=yes") -> 19393.5 | L19: =J19*E19/K19*C19 -> 0.36839708 | O19: 0.3652
A20: Dicarboxylic acids | B20: =VLOOKUP(A20, 'Compound Classes'!$A$6:$C$23, 3, FALSE) -> 3.4952909 | C20: 3.38 | D20: yes | E20: =IF(D20="yes",1,0) -> 1 | F20: adipic | G20: Pizzarello, S., & Huang, Y. (2002). Molecular and isotopic analyses of Tagish Lake alkyl dicarboxylic acids. Meteoritics and Planetary Science, 37(5), 687–696. https://doi.org/10.1111/j.1945-5100.2002.tb00848.x | H20: 19 | I20: 146.14 | J20: =H20*I20 -> 2776.66 | K20: =SUMIFS(J$2:J$116,A$2:A$116,A20,D$2:D$116,"=yes") -> 19393.5 | L20: =J20*E20/K20*C20 -> 0.48393074 | O20: 0.4826
A21: Dicarboxylic acids | B21: =VLOOKUP(A21, 'Compound Classes'!$A$6:$C$23, 3, FALSE) -> 3.4952909 | C21: 3.38 | D21: yes | E21: =IF(D21="yes",1,0) -> 1 | F21: glutaric | G21: Pizzarello, S., & Huang, Y. (2002). Molecular and isotopic analyses of Tagish Lake alkyl dicarboxylic acids. Meteoritics and Planetary Science, 37(5), 687–696. https://doi.org/10.1111/j.1945-5100.2002.tb00848.x | H21: 28 | I21: 132.11 | J21: =H21*I21 -> 3699.08 | K21: =SUMIFS(J$2:J$116,A$2:A$116,A21,D$2:D$116,"=yes") -> 19393.5 | L21: =J21*E21/K21*C21 -> 0.64469489 | O21: 0.9403
A22: Dicarboxylic acids | B22: =VLOOKUP(A22, 'Compound Classes'!$A$6:$C$23, 3, FALSE) -> 3.4952909 | C22: 3.38 | D22: yes | E22: =IF(D22="yes",1,0) -> 1 | F22: succinic | G22: Pizzarello, S., & Huang, Y. (2002). Molecular and isotopic analyses of Tagish Lake alkyl dicarboxylic acids. Meteoritics and Planetary Science, 37(5), 687–696. https://doi.org/10.1111/j.1945-5100.2002.tb00848.x | H22: 40 | I22: 270.1 | J22: =H22*I22 -> 10804 | K22: =SUMIFS(J$2:J$116,A$2:A$116,A22,D$2:D$116,"=yes") -> 19393.5 | L22: =J22*E22/K22*C22 -> 1.8829773 | O22: 1.8855
A23: Hydroxy acids | B23: =VLOOKUP(A23, 'Compound Classes'!$A$6:$C$23, 3, FALSE) -> 1.9856516 | C23: 1.92 | D23: yes | E23: =IF(D23="yes",1,0) -> 1 | F23: D,L-3-Hydroxybutyric | G23: Cronin, J. R., & Pizzarello, S. (1983). Amino acids in meteorites. Advances in Space Research, 3(9), 5–18. https://doi.org/10.1016/0273-1177(83)90036-43 | H23: 10.4 | I23: 104.1 | J23: =H23*I23 -> 1082.64 | K23: =SUMIFS(J$2:J$116,A$2:A$116,A23,D$2:D$116,"=yes") -> 68375.133 | L23: =J23*E23/K23*C23 -> 0.030400947 | O23: 0.0301
A24: Hydroxy acids | B24: =VLOOKUP(A24, 'Compound Classes'!$A$6:$C$23, 3, FALSE) -> 1.9856516 | C24: 1.92 | D24: yes | E24: =IF(D24="yes",1,0) -> 1 | F24: D,L-3-Hydroxyisobutyric | G24: Cronin, J. R., & Pizzarello, S. (1983). Amino acids in meteorites. Advances in Space Research, 3(9), 5–18. https://doi.org/10.1016/0273-1177(83)90036-44 | H24: 18.3 | I24: 104.1 | J24: =H24*I24 -> 1905.03 | K24: =SUMIFS(J$2:J$116,A$2:A$116,A24,D$2:D$116,"=yes") -> 68375.133 | L24: =J24*E24/K24*C24 -> 0.053493974 | N24: 1.126 | O24: 0.005 | P24: Out of Stock (Depleted)
A25: Hydroxy acids | B25: =VLOOKUP(A25, 'Compound Classes'!$A$6:$C$23, 3, FALSE) -> 1.9856516 | C25: 1.92 | D25: yes | E25: =IF(D25="yes",1,0) -> 1 | F25: L-2-Hydroxy-3-methylbutyric | G25: Cronin, J. R., & Pizzarello, S. (1983). Amino acids in meteorites. Advances in Space Research, 3(9), 5–18. https://doi.org/10.1016/0273-1177(83)90036-35 | H25: 18.3 | I25: 118.13 | J25: =H25*I25 -> 2161.779 | K25: =SUMIFS(J$2:J$116,A$2:A$116,A25,D$2:D$116,"=yes") -> 68375.133 | L25: =J25*E25/K25*C25 -> 0.060703584 | O25: 0.0618
A26: Hydroxy acids | B26: =VLOOKUP(A26, 'Compound Classes'!$A$6:$C$23, 3, FALSE) -> 1.9856516 | C26: 1.92 | D26: yes | E26: =IF(D26="yes",1,0) -> 1 | F26: D-2-Hydroxy-3-methylbutyric | G26: Cronin, J. R., & Pizzarello, S. (1983). Amino acids in meteorites. Advances in Space Research, 3(9), 5–18. https://doi.org/10.1016/0273-1177(83)90036-34 | H26: 18.6 | I26: 118.13 | J26: =H26*I26 -> 2197.218 | K26: =SUMIFS(J$2:J$116,A$2:A$116,A26,D$2:D$116,"=yes") -> 68375.133 | L26: =J26*E26/K26*C26 -> 0.061698725 | O26: 0.0618
A27: Hydroxy acids | B27: =VLOOKUP(A27, 'Compound Classes'!$A$6:$C$23, 3, FALSE) -> 1.9856516 | C27: 1.92 | D27: yes | E27: =IF(D27="yes",1,0) -> 1 | F27: 2-Hydroxyisobutyric | G27: Cronin, J. R., & Pizzarello, S. (1983). Amino acids in meteorites. Advances in Space Research, 3(9), 5–18. https://doi.org/10.1016/0273-1177(83)90036-31 | H27: 30 | I27: 104.1 | J27: =H27*I27 -> 3123 | K27: =SUMIFS(J$2:J$116,A$2:A$116,A27,D$2:D$116,"=yes") -> 68375.133 | L27: =J27*E27/K27*C27 -> 0.087695039 | O27: 0.0894
A28: Hydroxy acids | B28: =VLOOKUP(A28, 'Compound Classes'!$A$6:$C$23, 3, FALSE) -> 1.9856516 | C28: 1.92 | D28: yes | E28: =IF(D28="yes",1,0) -> 1 | F28: D-Lactic | G28: Cronin, J. R., & Pizzarello, S. (1983). Amino acids in meteorites. Advances in Space Research, 3(9), 5–18. https://doi.org/10.1016/0273-1177(83)90036-24 | H28: 39.9 | I28: 89.07 | J28: =H28*I28 -> 3553.893 | K28: =SUMIFS(J$2:J$116,A$2:A$116,A28,D$2:D$116,"=yes") -> 68375.133 | L28: =J28*E28/K28*C28 -> 0.09979468 | P28: No Stock
A29: Hydroxy acids | B29: =VLOOKUP(A29, 'Compound Classes'!$A$6:$C$23, 3, FALSE) -> 1.9856516 | C29: 1.92 | D29: yes | E29: =IF(D29="yes",1,0) -> 1 | F29: L-Lactic | G29: Cronin, J. R., & Pizzarello, S. (1983). Amino acids in meteorites. Advances in Space Research, 3(9), 5–18. https://doi.org/10.1016/0273-1177(83)90036-25 | H29: 44.3 | I29: 90.08 | J29: =H29*I29 -> 3990.544 | K29: =SUMIFS(J$2:J$116,A$2:A$116,A29,D$2:D$116,"=yes") -> 68375.133 | L29: =J29*E29/K29*C29 -> 0.11205601 | N29: 1.21 | O29: 0.1135
A30: Hydroxy acids | B30: =VLOOKUP(A30, 'Compound Classes'!$A$6:$C$23, 3, FALSE) -> 1.9856516 | C30: 1.92 | D30: yes | E30: =IF(D30="yes",1,0) -> 1 | F30: b-Lactic | G30: Cronin, J. R., & Pizzarello, S. (1983). Amino acids in meteorites. Advances in Space Research, 3(9), 5–18. https://doi.org/10.1016/0273-1177(83)90036-42 | H30: 51.5 | I30: 90.08 | J30: =H30*I30 -> 4639.12 | K30: =SUMIFS(J$2:J$116,A$2:A$116,A30,D$2:D$116,"=yes") -> 68375.133 | L30: =J30*E30/K30*C30 -> 0.13026827 | P30: No Stock
A31: Hydroxy acids | B31: =VLOOKUP(A31, 'Compound Classes'!$A$6:$C$23, 3, FALSE) -> 1.9856516 | C31: 1.92 | D31: yes | E31: =IF(D31="yes",1,0) -> 1 | F31: Glycolic | G31: Cronin, J. R., & Pizzarello, S. (1983). Amino acids in meteorites. Advances in Space Research, 3(9), 5–18. https://doi.org/10.1016/0273-1177(83)90036-23 | H31: 65 | I31: 76.05 | J31: =H31*I31 -> 4943.25 | K31: =SUMIFS(J$2:J$116,A$2:A$116,A31,D$2:D$116,"=yes") -> 68375.133 | L31: =J31*E31/K31*C31 -> 0.13880836 | O31: 0.1371
A32: Hydroxy acids | B32: =VLOOKUP(A32, 'Compound Classes'!$A$6:$C$23, 3, FALSE) -> 1.9856516 | C32: 1.92 | D32: yes | E32: =IF(D32="yes",1,0) -> 1 | F32: D,L-2-alloHydroxy-3-methylvaleric | G32: Cronin, J. R., & Pizzarello, S. (1983). Amino acids in meteorites. Advances in Space Research, 3(9), 5–18. https://doi.org/10.1016/0273-1177(83)90036-41 | H32: 61 | I32: 131.15 | J32: =H32*I32 -> 8000.15 | K32: =SUMIFS(J$2:J$116,A$2:A$116,A32,D$2:D$116,"=yes") -> 68375.133 | L32: =J32*E32/K32*C32 -> 0.22464728 | P32: No Stock
A33: Hydroxy acids | B33: =VLOOKUP(A33, 'Compound Classes'!$A$6:$C$23, 3, FALSE) -> 1.9856516 | C33: 1.92 | D33: yes | E33: =IF(D33="yes",1,0) -> 1 | F33: D,L-2-Hydroxyisocaproic (Leucic Acid) | G33: Cronin, J. R., & Pizzarello, S. (1983). Amino acids in meteorites. Advances in Space Research, 3(9), 5–18. https://doi.org/10.1016/0273-1177(83)90036-39 | H33: 61 | I33: 132.16 | J33: =H33*I33 -> 8061.76 | K33: =SUMIFS(J$2:J$116,A$2:A$116,A33,D$2:D$116,"=yes") -> 68375.133 | L33: =J33*E33/K33*C33 -> 0.22637732 | O33: 0.2243
A34: Hydroxy acids | B34: =VLOOKUP(A34, 'Compound Classes'!$A$6:$C$23, 3, FALSE) -> 1.9856516 | C34: 1.92 | D34: yes | E34: =IF(D34="yes",1,0) -> 1 | F34: D,L-2-Hydroxy-3-methylvaleric | G34: Cronin, J. R., & Pizzarello, S. (1983). Amino acids in meteorites. Advances in Space Research, 3(9), 5–18. https://doi.org/10.1016/0273-1177(83)90036-40 | H34: 61 | I34: 132.16 | J34: =H34*I34 -> 8061.76 | K34: =SUMIFS(J$2:J$116,A$2:A$116,A34,D$2:D$116,"=yes") -> 68375.133 | L34: =J34*E34/K34*C34 -> 0.22637732 | P34: No Stock
A35: Hydroxy acids | B35: =VLOOKUP(A35, 'Compound Classes'!$A$6:$C$23, 3, FALSE) -> 1.9856516 | C35: 1.92 | D35: yes | E35: =IF(D35="yes",1,0) -> 1 | F35: D,L-2-Hydroxyglutaric | G35: Cronin, J. R., & Pizzarello, S. (1983). Amino acids in meteorites. Advances in Space Research, 3(9), 5–18. https://doi.org/10.1016/0273-1177(83)90036-45 | H35: 54.45 | I35: 148.11 | J35: =H35*I35 -> 8064.5895 | K35: =SUMIFS(J$2:J$116,A$2:A$116,A35,D$2:D$116,"=yes") -> 68375.133 | L35: =J35*E35/K35*C35 -> 0.22645677 | O35: 0.01 | P35: Out of Stock (Depleted)
A36: Hydroxy acids | B36: =VLOOKUP(A36, 'Compound Classes'!$A$6:$C$23, 3, FALSE) -> 1.9856516 | C36: 1.92 | D36: yes | E36: =IF(D36="yes",1,0) -> 1 | F36: D,L-2-Hydroxycaproic (2-Hydroxyhexanoic acid) | G36: Cronin, J. R., & Pizzarello, S. (1983). Amino acids in meteorites. Advances in Space Research, 3(9), 5–18. https://doi.org/10.1016/0273-1177(83)90036-30 | H36: 65 | I36: 132.16 | J36: =H36*I36 -> 8590.4 | K36: =SUMIFS(J$2:J$116,A$2:A$116,A36,D$2:D$116,"=yes") -> 68375.133 | L36: =J36*E36/K36*C36 -> 0.24122173 | O36: 0.2405
A37: Imino acids | B37: =VLOOKUP(A37, 'Compound Classes'!$A$6:$C$23, 3, FALSE) -> #N/A | C37: trace | D37: yes | E37: =IF(D37="yes",1,0) -> 1 | F37: iminopropionicacetic* | G37: Lerner, N. R., & Cooper, G. W. (2005). Iminodicarboxylic acids in the Murchison meteorite: Evidence of Strecker reactions. Geochimica et Cosmochimica Acta, 69(11), 2901–2906. https://doi.org/https://doi.org/10.1016/j.gca.2004.12.025 | H37: 15 | I37: 148.12 | J37: =H37*I37 -> 2221.8 | K37: =SUMIFS(J$2:J$116,A$2:A$116,A37,D$2:D$116,"=yes") -> 2221.8 | L37: trace | M37: nmol/g estimated based on glycine value | P37: No Stock
A38: monoCarboxylic acids | B38: =VLOOKUP(A38, 'Compound Classes'!$A$6:$C$23, 3, FALSE) -> 45.153174 | C38: 43.668409 | D38: yes | E38: =IF(D38="yes",1,0) -> 1 | F38: 3,6-dimethylheptanoic | G38: Huang, Y., Wang, Y., Alexandre, M. R., Lee, T., Rose-Petruck, C., Fuller, M., & Pizzarello, S. (2005). Molecular and compound-specific isotopic characterization of monocarboxylic acids in carboneous meteorites. Geochim. Cosmochim. Acta, 69, 1073–1084. Retrieved from Am, pdf | H38: 84.4 | I38: 158.24 | J38: =H38*I38 -> 13355.456 | K38: =SUMIFS(J$2:J$116,A$2:A$116,A38,D$2:D$116,"=yes") -> 698435.88 | L38: =J38*E38/K38*C38 -> 0.83502515 | P38: No Stock
A39: monoCarboxylic acids | B39: =VLOOKUP(A39, 'Compound Classes'!$A$6:$C$23, 3, FALSE) -> 45.153174 | C39: 43.668409 | D39: yes | E39: =IF(D39="yes",1,0) -> 1 | F39: Formic | G39: Huang, Y., Wang, Y., Alexandre, M. R., Lee, T., Rose-Petruck, C., Fuller, M., & Pizzarello, S. (2005). Molecular and compound-specific isotopic characterization of monocarboxylic acids in carboneous meteorites. Geochim. Cosmochim. Acta, 69, 1073–1084. Retrieved from Am, pdf | H39: 42 | I39: 46.025 | J39: =H39*I39 -> 1933.05 | K39: =SUMIFS(J$2:J$116,A$2:A$116,A39,D$2:D$116,"=yes") -> 698435.88 | L39: =J39*E39/K39*C39 -> 0.12086037 | N39: 1.22 | O39: 0.1261
A40: monoCarboxylic acids | B40: =VLOOKUP(A40, 'Compound Classes'!$A$6:$C$23, 3, FALSE) -> 45.153174 | C40: 43.668409 | D40: yes | E40: =IF(D40="yes",1,0) -> 1 | F40: 2-ethylbutanoic acid | G40: Huang, Y., Wang, Y., Alexandre, M. R., Lee, T., Rose-Petruck, C., Fuller, M., & Pizzarello, S. (2005). Molecular and compound-specific isotopic characterization of monocarboxylic acids in carboneous meteorites. Geochim. Cosmochim. Acta, 69, 1073–1084. Retrieved from Am, pdf | H40: 37.4 | I40: 116.16 | J40: =H40*I40 -> 4344.384 | K40: =SUMIFS(J$2:J$116,A$2:A$116,A40,D$2:D$116,"=yes") -> 698435.88 | L40: =J40*E40/K40*C40 -> 0.27162456 | N40: 0.92 | O40: 0.2774
...
